Workbook

Sheet Deal Breakdown
A1: Palisades lots — deal breakdown for the shortlist
A2: ="Construction at $"&TEXT(Assumptions!$B$4,"#,##0")&"/sf fixed. Cost breakdown shows the "&Assumptions!$B$31&" case; all three cases are at the bottom. Change inputs on the Assumptions tab." -> Construction at $700/sf fixed. Cost breakdown shows the Medium case; all three cases are at the bottom. Change inputs on the Assumptions tab.
A3: Every number is pulled live from the All Lots tab. Sale prices start from closed sales by neighborhood; Worst = today's comps, Medium = +10%, Best = +20%.
B5: 711 Chapala | C5: 611 Ocampo | D5: 16150 Northfield | E5: 14410 Villa Woods | F5: 909 Rivas Canyon | G5: 545 N Las Casas
A6: THE LOT
A7: Neighborhood | B7: =INDEX('All Lots'!$C$3:$C$138,MATCH("711 Chapala Dr",'All Lots'!$B$3:$B$138,0)) -> Huntington | C7: =INDEX('All Lots'!$C$3:$C$138,MATCH("611 Ocampo Dr",'All Lots'!$B$3:$B$138,0)) -> Huntington | D7: =INDEX('All Lots'!$C$3:$C$138,MATCH("16150 Northfield St",'All Lots'!$B$3:$B$138,0)) -> Bluffs / El Medio | E7: =INDEX('All Lots'!$C$3:$C$138,MATCH("14410 Villa Woods Pl",'All Lots'!$B$3:$B$138,0)) -> Riviera | F7: =INDEX('All Lots'!$C$3:$C$138,MATCH("909 Rivas Canyon Rd",'All Lots'!$B$3:$B$138,0)) -> Riviera | G7: =INDEX('All Lots'!$C$3:$C$138,MATCH("545 N Las Casas Ave",'All Lots'!$B$3:$B$138,0)) -> Bluffs / El Medio
A8: Asking price | B8: =INDEX('All Lots'!$D$3:$D$138,MATCH("711 Chapala Dr",'All Lots'!$B$3:$B$138,0)) -> 4375000 | C8: =INDEX('All Lots'!$D$3:$D$138,MATCH("611 Ocampo Dr",'All Lots'!$B$3:$B$138,0)) -> 4495000 | D8: =INDEX('All Lots'!$D$3:$D$138,MATCH("16150 Northfield St",'All Lots'!$B$3:$B$138,0)) -> 1395000 | E8: =INDEX('All Lots'!$D$3:$D$138,MATCH("14410 Villa Woods Pl",'All Lots'!$B$3:$B$138,0)) -> 2795000 | F8: =INDEX('All Lots'!$D$3:$D$138,MATCH("909 Rivas Canyon Rd",'All Lots'!$B$3:$B$138,0)) -> 3750000 | G8: =INDEX('All Lots'!$D$3:$D$138,MATCH("545 N Las Casas Ave",'All Lots'!$B$3:$B$138,0)) -> 995000
A9: Lot size (sf) | B9: =INDEX('All Lots'!$E$3:$E$138,MATCH("711 Chapala Dr",'All Lots'!$B$3:$B$138,0)) -> 8008 | C9: =INDEX('All Lots'!$E$3:$E$138,MATCH("611 Ocampo Dr",'All Lots'!$B$3:$B$138,0)) -> 8205 | D9: =INDEX('All Lots'!$E$3:$E$138,MATCH("16150 Northfield St",'All Lots'!$B$3:$B$138,0)) -> 5556 | E9: =INDEX('All Lots'!$E$3:$E$138,MATCH("14410 Villa Woods Pl",'All Lots'!$B$3:$B$138,0)) -> 13724 | F9: =INDEX('All Lots'!$E$3:$E$138,MATCH("909 Rivas Canyon Rd",'All Lots'!$B$3:$B$138,0)) -> 18344 | G9: =INDEX('All Lots'!$E$3:$E$138,MATCH("545 N Las Casas Ave",'All Lots'!$B$3:$B$138,0)) -> 4382
A10: City-approved plans? | B10: =INDEX('All Lots'!$H$3:$H$138,MATCH("711 Chapala Dr",'All Lots'!$B$3:$B$138,0)) -> Yes | C10: =INDEX('All Lots'!$H$3:$H$138,MATCH("611 Ocampo Dr",'All Lots'!$B$3:$B$138,0)) -> Yes | D10: =INDEX('All Lots'!$H$3:$H$138,MATCH("16150 Northfield St",'All Lots'!$B$3:$B$138,0)) -> Yes | E10: =INDEX('All Lots'!$H$3:$H$138,MATCH("14410 Villa Woods Pl",'All Lots'!$B$3:$B$138,0)) -> No | F10: =INDEX('All Lots'!$H$3:$H$138,MATCH("909 Rivas Canyon Rd",'All Lots'!$B$3:$B$138,0)) -> No | G10: =INDEX('All Lots'!$H$3:$H$138,MATCH("545 N Las Casas Ave",'All Lots'!$B$3:$B$138,0)) -> No
A11: THE HOUSE
A12: New house size (sf) | B12: =INDEX('All Lots'!$L$3:$L$138,MATCH("711 Chapala Dr",'All Lots'!$B$3:$B$138,0)) -> 7504 | C12: =INDEX('All Lots'!$L$3:$L$138,MATCH("611 Ocampo Dr",'All Lots'!$B$3:$B$138,0)) -> 7154 | D12: =INDEX('All Lots'!$L$3:$L$138,MATCH("16150 Northfield St",'All Lots'!$B$3:$B$138,0)) -> 4270 | E12: =INDEX('All Lots'!$L$3:$L$138,MATCH("14410 Villa Woods Pl",'All Lots'!$B$3:$B$138,0)) -> 5490 | F12: =INDEX('All Lots'!$L$3:$L$138,MATCH("909 Rivas Canyon Rd",'All Lots'!$B$3:$B$138,0)) -> 7338 | G12: =INDEX('All Lots'!$L$3:$L$138,MATCH("545 N Las Casas Ave",'All Lots'!$B$3:$B$138,0)) -> 3315
A13: How sized | B13: =INDEX('All Lots'!$M$3:$M$138,MATCH("711 Chapala Dr",'All Lots'!$B$3:$B$138,0)) -> Approved plans | C13: =INDEX('All Lots'!$M$3:$M$138,MATCH("611 Ocampo Dr",'All Lots'!$B$3:$B$138,0)) -> Approved plans | D13: =INDEX('All Lots'!$M$3:$M$138,MATCH("16150 Northfield St",'All Lots'!$B$3:$B$138,0)) -> Approved plans | E13: =INDEX('All Lots'!$M$3:$M$138,MATCH("14410 Villa Woods Pl",'All Lots'!$B$3:$B$138,0)) -> Zoning estimate | F13: =INDEX('All Lots'!$M$3:$M$138,MATCH("909 Rivas Canyon Rd",'All Lots'!$B$3:$B$138,0)) -> Zoning estimate | G13: =INDEX('All Lots'!$M$3:$M$138,MATCH("545 N Las Casas Ave",'All Lots'!$B$3:$B$138,0)) -> 110% old house
A14: Sale price per sf | B14: =INDEX('All Lots'!$O$3:$O$138,MATCH("711 Chapala Dr",'All Lots'!$B$3:$B$138,0)) -> 2035 | C14: =INDEX('All Lots'!$O$3:$O$138,MATCH("611 Ocampo Dr",'All Lots'!$B$3:$B$138,0)) -> 2035 | D14: =INDEX('All Lots'!$O$3:$O$138,MATCH("16150 Northfield St",'All Lots'!$B$3:$B$138,0)) -> 1540 | E14: =INDEX('All Lots'!$O$3:$O$138,MATCH("14410 Villa Woods Pl",'All Lots'!$B$3:$B$138,0)) -> 2046 | F14: =INDEX('All Lots'!$O$3:$O$138,MATCH("909 Rivas Canyon Rd",'All Lots'!$B$3:$B$138,0)) -> 2046 | G14: =INDEX('All Lots'!$O$3:$O$138,MATCH("545 N Las Casas Ave",'All Lots'!$B$3:$B$138,0)) -> 1540
A15: Projected sale price | B15: =INDEX('All Lots'!$P$3:$P$138,MATCH("711 Chapala Dr",'All Lots'!$B$3:$B$138,0)) -> 15270640 | C15: =INDEX('All Lots'!$P$3:$P$138,MATCH("611 Ocampo Dr",'All Lots'!$B$3:$B$138,0)) -> 14558390 | D15: =INDEX('All Lots'!$P$3:$P$138,MATCH("16150 Northfield St",'All Lots'!$B$3:$B$138,0)) -> 6575800 | E15: =INDEX('All Lots'!$P$3:$P$138,MATCH("14410 Villa Woods Pl",'All Lots'!$B$3:$B$138,0)) -> 11232540 | F15: =INDEX('All Lots'!$P$3:$P$138,MATCH("909 Rivas Canyon Rd",'All Lots'!$B$3:$B$138,0)) -> 15013548 | G15: =INDEX('All Lots'!$P$3:$P$138,MATCH("545 N Las Casas Ave",'All Lots'!$B$3:$B$138,0)) -> 5105100
A16: COSTS
A17: Land | B17: =INDEX('All Lots'!$Q$3:$Q$138,MATCH("711 Chapala Dr",'All Lots'!$B$3:$B$138,0)) -> 4375000 | C17: =INDEX('All Lots'!$Q$3:$Q$138,MATCH("611 Ocampo Dr",'All Lots'!$B$3:$B$138,0)) -> 4495000 | D17: =INDEX('All Lots'!$Q$3:$Q$138,MATCH("16150 Northfield St",'All Lots'!$B$3:$B$138,0)) -> 1395000 | E17: =INDEX('All Lots'!$Q$3:$Q$138,MATCH("14410 Villa Woods Pl",'All Lots'!$B$3:$B$138,0)) -> 2795000 | F17: =INDEX('All Lots'!$Q$3:$Q$138,MATCH("909 Rivas Canyon Rd",'All Lots'!$B$3:$B$138,0)) -> 3750000 | G17: =INDEX('All Lots'!$Q$3:$Q$138,MATCH("545 N Las Casas Ave",'All Lots'!$B$3:$B$138,0)) -> 995000
A18: Construction | B18: =INDEX('All Lots'!$R$3:$R$138,MATCH("711 Chapala Dr",'All Lots'!$B$3:$B$138,0)) -> 5252800 | C18: =INDEX('All Lots'!$R$3:$R$138,MATCH("611 Ocampo Dr",'All Lots'!$B$3:$B$138,0)) -> 5007800 | D18: =INDEX('All Lots'!$R$3:$R$138,MATCH("16150 Northfield St",'All Lots'!$B$3:$B$138,0)) -> 2989000 | E18: =INDEX('All Lots'!$R$3:$R$138,MATCH("14410 Villa Woods Pl",'All Lots'!$B$3:$B$138,0)) -> 3843000 | F18: =INDEX('All Lots'!$R$3:$R$138,MATCH("909 Rivas Canyon Rd",'All Lots'!$B$3:$B$138,0)) -> 5136600 | G18: =INDEX('All Lots'!$R$3:$R$138,MATCH("545 N Las Casas Ave",'All Lots'!$B$3:$B$138,0)) -> 2320500
A19: Design, permits & fees (or 5% reserve) | B19: =INDEX('All Lots'!$S$3:$S$138,MATCH("711 Chapala Dr",'All Lots'!$B$3:$B$138,0)) -> 218750 | C19: =INDEX('All Lots'!$S$3:$S$138,MATCH("611 Ocampo Dr",'All Lots'!$B$3:$B$138,0)) -> 224750 | D19: =INDEX('All Lots'!$S$3:$S$138,MATCH("16150 Northfield St",'All Lots'!$B$3:$B$138,0)) -> 69750 | E19: =INDEX('All Lots'!$S$3:$S$138,MATCH("14410 Villa Woods Pl",'All Lots'!$B$3:$B$138,0)) -> 411750 | F19: =INDEX('All Lots'!$S$3:$S$138,MATCH("909 Rivas Canyon Rd",'All Lots'!$B$3:$B$138,0)) -> 550350 | G19: =INDEX('All Lots'!$S$3:$S$138,MATCH("545 N Las Casas Ave",'All Lots'!$B$3:$B$138,0)) -> 248625
A20: Loan interest & points | B20: =INDEX('All Lots'!$T$3:$T$138,MATCH("711 Chapala Dr",'All Lots'!$B$3:$B$138,0)) -> 864034.76 | C20: =INDEX('All Lots'!$T$3:$T$138,MATCH("611 Ocampo Dr",'All Lots'!$B$3:$B$138,0)) -> 853592.51 | D20: =INDEX('All Lots'!$T$3:$T$138,MATCH("16150 Northfield St",'All Lots'!$B$3:$B$138,0)) -> 390816.56 | E20: =INDEX('All Lots'!$T$3:$T$138,MATCH("14410 Villa Woods Pl",'All Lots'!$B$3:$B$138,0)) -> 893555.81 | F20: =INDEX('All Lots'!$T$3:$T$138,MATCH("909 Rivas Canyon Rd",'All Lots'!$B$3:$B$138,0)) -> 1196133.4 | G20: =INDEX('All Lots'!$T$3:$T$138,MATCH("545 N Las Casas Ave",'All Lots'!$B$3:$B$138,0)) -> 312751.97
A21: Property tax | B21: =INDEX('All Lots'!$U$3:$U$138,MATCH("711 Chapala Dr",'All Lots'!$B$3:$B$138,0)) -> 105000 | C21: =INDEX('All Lots'!$U$3:$U$138,MATCH("611 Ocampo Dr",'All Lots'!$B$3:$B$138,0)) -> 107880 | D21: =INDEX('All Lots'!$U$3:$U$138,MATCH("16150 Northfield St",'All Lots'!$B$3:$B$138,0)) -> 33480 | E21: =INDEX('All Lots'!$U$3:$U$138,MATCH("14410 Villa Woods Pl",'All Lots'!$B$3:$B$138,0)) -> 100620 | F21: =INDEX('All Lots'!$U$3:$U$138,MATCH("909 Rivas Canyon Rd",'All Lots'!$B$3:$B$138,0)) -> 135000 | G21: =INDEX('All Lots'!$U$3:$U$138,MATCH("545 N Las Casas Ave",'All Lots'!$B$3:$B$138,0)) -> 23880
A22: Commission & transfer tax | B22: =INDEX('All Lots'!$V$3:$V$138,MATCH("711 Chapala Dr",'All Lots'!$B$3:$B$138,0)) -> 619987.98 | C22: =INDEX('All Lots'!$V$3:$V$138,MATCH("611 Ocampo Dr",'All Lots'!$B$3:$B$138,0)) -> 591070.63 | D22: =INDEX('All Lots'!$V$3:$V$138,MATCH("16150 Northfield St",'All Lots'!$B$3:$B$138,0)) -> 266977.48 | E22: =INDEX('All Lots'!$V$3:$V$138,MATCH("14410 Villa Woods Pl",'All Lots'!$B$3:$B$138,0)) -> 456041.12 | F22: =INDEX('All Lots'!$V$3:$V$138,MATCH("909 Rivas Canyon Rd",'All Lots'!$B$3:$B$138,0)) -> 609550.05 | G22: =INDEX('All Lots'!$V$3:$V$138,MATCH("545 N Las Casas Ave",'All Lots'!$B$3:$B$138,0)) -> 207267.06
A23: Mansion tax (ULA) | B23: =INDEX('All Lots'!$W$3:$W$138,MATCH("711 Chapala Dr",'All Lots'!$B$3:$B$138,0)) -> 839885.2 | C23: =INDEX('All Lots'!$W$3:$W$138,MATCH("611 Ocampo Dr",'All Lots'!$B$3:$B$138,0)) -> 800711.45 | D23: =INDEX('All Lots'!$W$3:$W$138,MATCH("16150 Northfield St",'All Lots'!$B$3:$B$138,0)) -> 263032 | E23: =INDEX('All Lots'!$W$3:$W$138,MATCH("14410 Villa Woods Pl",'All Lots'!$B$3:$B$138,0)) -> 617789.7 | F23: =INDEX('All Lots'!$W$3:$W$138,MATCH("909 Rivas Canyon Rd",'All Lots'!$B$3:$B$138,0)) -> 825745.14 | G23: =INDEX('All Lots'!$W$3:$W$138,MATCH("545 N Las Casas Ave",'All Lots'!$B$3:$B$138,0)) -> 0
A24: Total cost | B24: =INDEX('All Lots'!$X$3:$X$138,MATCH("711 Chapala Dr",'All Lots'!$B$3:$B$138,0)) -> 12275458 | C24: =INDEX('All Lots'!$X$3:$X$138,MATCH("611 Ocampo Dr",'All Lots'!$B$3:$B$138,0)) -> 12080805 | D24: =INDEX('All Lots'!$X$3:$X$138,MATCH("16150 Northfield St",'All Lots'!$B$3:$B$138,0)) -> 5408056 | E24: =INDEX('All Lots'!$X$3:$X$138,MATCH("14410 Villa Woods Pl",'All Lots'!$B$3:$B$138,0)) -> 9117756.6 | F24: =INDEX('All Lots'!$X$3:$X$138,MATCH("909 Rivas Canyon Rd",'All Lots'!$B$3:$B$138,0)) -> 12203379 | G24: =INDEX('All Lots'!$X$3:$X$138,MATCH("545 N Las Casas Ave",'All Lots'!$B$3:$B$138,0)) -> 4108024
A25: RETURNS
A26: Profit | B26: =INDEX('All Lots'!$Y$3:$Y$138,MATCH("711 Chapala Dr",'All Lots'!$B$3:$B$138,0)) -> 2995182.1 | C26: =INDEX('All Lots'!$Y$3:$Y$138,MATCH("611 Ocampo Dr",'All Lots'!$B$3:$B$138,0)) -> 2477585.4 | D26: =INDEX('All Lots'!$Y$3:$Y$138,MATCH("16150 Northfield St",'All Lots'!$B$3:$B$138,0)) -> 1167744 | E26: =INDEX('All Lots'!$Y$3:$Y$138,MATCH("14410 Villa Woods Pl",'All Lots'!$B$3:$B$138,0)) -> 2114783.4 | F26: =INDEX('All Lots'!$Y$3:$Y$138,MATCH("909 Rivas Canyon Rd",'All Lots'!$B$3:$B$138,0)) -> 2810169.4 | G26: =INDEX('All Lots'!$Y$3:$Y$138,MATCH("545 N Las Casas Ave",'All Lots'!$B$3:$B$138,0)) -> 997075.97
A27: Margin (profit ÷ cost) | B27: =INDEX('All Lots'!$Z$3:$Z$138,MATCH("711 Chapala Dr",'All Lots'!$B$3:$B$138,0)) -> 0.24399758 | C27: =INDEX('All Lots'!$Z$3:$Z$138,MATCH("611 Ocampo Dr",'All Lots'!$B$3:$B$138,0)) -> 0.20508447 | D27: =INDEX('All Lots'!$Z$3:$Z$138,MATCH("16150 Northfield St",'All Lots'!$B$3:$B$138,0)) -> 0.21592675 | E27: =INDEX('All Lots'!$Z$3:$Z$138,MATCH("14410 Villa Woods Pl",'All Lots'!$B$3:$B$138,0)) -> 0.23194119 | F27: =INDEX('All Lots'!$Z$3:$Z$138,MATCH("909 Rivas Canyon Rd",'All Lots'!$B$3:$B$138,0)) -> 0.23027798 | G27: =INDEX('All Lots'!$Z$3:$Z$138,MATCH("545 N Las Casas Ave",'All Lots'!$B$3:$B$138,0)) -> 0.24271425
A28: Most we should pay for the lot | B28: =INDEX('All Lots'!$AA$3:$AA$138,MATCH("711 Chapala Dr",'All Lots'!$B$3:$B$138,0)) -> 5235412.6 | C28: =INDEX('All Lots'!$AA$3:$AA$138,MATCH("611 Ocampo Dr",'All Lots'!$B$3:$B$138,0)) -> 4991223.6 | D28: =INDEX('All Lots'!$AA$3:$AA$138,MATCH("16150 Northfield St",'All Lots'!$B$3:$B$138,0)) -> 1660861.4 | E28: =INDEX('All Lots'!$AA$3:$AA$138,MATCH("14410 Villa Woods Pl",'All Lots'!$B$3:$B$138,0)) -> 3353735.3 | F28: =INDEX('All Lots'!$AA$3:$AA$138,MATCH("909 Rivas Canyon Rd",'All Lots'!$B$3:$B$138,0)) -> 4482642.9 | G28: =INDEX('All Lots'!$AA$3:$AA$138,MATCH("545 N Las Casas Ave",'All Lots'!$B$3:$B$138,0)) -> 1292902.7
A29: Asking vs. most we should pay | B29: =INDEX('All Lots'!$AB$3:$AB$138,MATCH("711 Chapala Dr",'All Lots'!$B$3:$B$138,0)) -> 0.83565524 | C29: =INDEX('All Lots'!$AB$3:$AB$138,MATCH("611 Ocampo Dr",'All Lots'!$B$3:$B$138,0)) -> 0.90058077 | D29: =INDEX('All Lots'!$AB$3:$AB$138,MATCH("16150 Northfield St",'All Lots'!$B$3:$B$138,0)) -> 0.83992561 | E29: =INDEX('All Lots'!$AB$3:$AB$138,MATCH("14410 Villa Woods Pl",'All Lots'!$B$3:$B$138,0)) -> 0.83339911 | F29: =INDEX('All Lots'!$AB$3:$AB$138,MATCH("909 Rivas Canyon Rd",'All Lots'!$B$3:$B$138,0)) -> 0.83656006 | G29: =INDEX('All Lots'!$AB$3:$AB$138,MATCH("545 N Las Casas Ave",'All Lots'!$B$3:$B$138,0)) -> 0.76958612
A30: PROFIT IN EACH SCENARIO
A31: Worst: sale price per sf (today's comps) | B31: =INDEX('All Lots'!$AC$3:$AC$138,MATCH("711 Chapala Dr",'All Lots'!$B$3:$B$138,0)) -> 1850 | C31: =INDEX('All Lots'!$AC$3:$AC$138,MATCH("611 Ocampo Dr",'All Lots'!$B$3:$B$138,0)) -> 1850 | D31: =INDEX('All Lots'!$AC$3:$AC$138,MATCH("16150 Northfield St",'All Lots'!$B$3:$B$138,0)) -> 1400 | E31: =INDEX('All Lots'!$AC$3:$AC$138,MATCH("14410 Villa Woods Pl",'All Lots'!$B$3:$B$138,0)) -> 1860 | F31: =INDEX('All Lots'!$AC$3:$AC$138,MATCH("909 Rivas Canyon Rd",'All Lots'!$B$3:$B$138,0)) -> 1860 | G31: =INDEX('All Lots'!$AC$3:$AC$138,MATCH("545 N Las Casas Ave",'All Lots'!$B$3:$B$138,0)) -> 1400
A32: Worst: profit | B32: =INDEX('All Lots'!$AD$3:$AD$138,MATCH("711 Chapala Dr",'All Lots'!$B$3:$B$138,0)) -> 1739657.8 | C32: =INDEX('All Lots'!$AD$3:$AD$138,MATCH("611 Ocampo Dr",'All Lots'!$B$3:$B$138,0)) -> 1280621 | D32: =INDEX('All Lots'!$AD$3:$AD$138,MATCH("16150 Northfield St",'All Lots'!$B$3:$B$138,0)) -> 618126.64 | E32: =INDEX('All Lots'!$AD$3:$AD$138,MATCH("14410 Villa Woods Pl",'All Lots'!$B$3:$B$138,0)) -> 1344435.3 | F32: =INDEX('All Lots'!$AD$3:$AD$138,MATCH("909 Rivas Canyon Rd",'All Lots'!$B$3:$B$138,0)) -> 1575782.8 | G32: =INDEX('All Lots'!$AD$3:$AD$138,MATCH("545 N Las Casas Ave",'All Lots'!$B$3:$B$138,0)) -> 551818.43
A33: Medium: sale price per sf (+10%) | B33: =INDEX('All Lots'!$AE$3:$AE$138,MATCH("711 Chapala Dr",'All Lots'!$B$3:$B$138,0)) -> 2035 | C33: =INDEX('All Lots'!$AE$3:$AE$138,MATCH("611 Ocampo Dr",'All Lots'!$B$3:$B$138,0)) -> 2035 | D33: =INDEX('All Lots'!$AE$3:$AE$138,MATCH("16150 Northfield St",'All Lots'!$B$3:$B$138,0)) -> 1540 | E33: =INDEX('All Lots'!$AE$3:$AE$138,MATCH("14410 Villa Woods Pl",'All Lots'!$B$3:$B$138,0)) -> 2046 | F33: =INDEX('All Lots'!$AE$3:$AE$138,MATCH("909 Rivas Canyon Rd",'All Lots'!$B$3:$B$138,0)) -> 2046 | G33: =INDEX('All Lots'!$AE$3:$AE$138,MATCH("545 N Las Casas Ave",'All Lots'!$B$3:$B$138,0)) -> 1540
A34: Medium: profit | B34: =INDEX('All Lots'!$AF$3:$AF$138,MATCH("711 Chapala Dr",'All Lots'!$B$3:$B$138,0)) -> 2995182.1 | C34: =INDEX('All Lots'!$AF$3:$AF$138,MATCH("611 Ocampo Dr",'All Lots'!$B$3:$B$138,0)) -> 2477585.4 | D34: =INDEX('All Lots'!$AF$3:$AF$138,MATCH("16150 Northfield St",'All Lots'!$B$3:$B$138,0)) -> 1167744 | E34: =INDEX('All Lots'!$AF$3:$AF$138,MATCH("14410 Villa Woods Pl",'All Lots'!$B$3:$B$138,0)) -> 2114783.4 | F34: =INDEX('All Lots'!$AF$3:$AF$138,MATCH("909 Rivas Canyon Rd",'All Lots'!$B$3:$B$138,0)) -> 2810169.4 | G34: =INDEX('All Lots'!$AF$3:$AF$138,MATCH("545 N Las Casas Ave",'All Lots'!$B$3:$B$138,0)) -> 997075.97
A35: Best: sale price per sf (+20%) | B35: =INDEX('All Lots'!$AG$3:$AG$138,MATCH("711 Chapala Dr",'All Lots'!$B$3:$B$138,0)) -> 2220 | C35: =INDEX('All Lots'!$AG$3:$AG$138,MATCH("611 Ocampo Dr",'All Lots'!$B$3:$B$138,0)) -> 2220 | D35: =INDEX('All Lots'!$AG$3:$AG$138,MATCH("16150 Northfield St",'All Lots'!$B$3:$B$138,0)) -> 1680 | E35: =INDEX('All Lots'!$AG$3:$AG$138,MATCH("14410 Villa Woods Pl",'All Lots'!$B$3:$B$138,0)) -> 2232 | F35: =INDEX('All Lots'!$AG$3:$AG$138,MATCH("909 Rivas Canyon Rd",'All Lots'!$B$3:$B$138,0)) -> 2232 | G35: =INDEX('All Lots'!$AG$3:$AG$138,MATCH("545 N Las Casas Ave",'All Lots'!$B$3:$B$138,0)) -> 1680
A36: Best: profit | B36: =INDEX('All Lots'!$AH$3:$AH$138,MATCH("711 Chapala Dr",'All Lots'!$B$3:$B$138,0)) -> 4250706.3 | C36: =INDEX('All Lots'!$AH$3:$AH$138,MATCH("611 Ocampo Dr",'All Lots'!$B$3:$B$138,0)) -> 3674549.8 | D36: =INDEX('All Lots'!$AH$3:$AH$138,MATCH("16150 Northfield St",'All Lots'!$B$3:$B$138,0)) -> 1717361.3 | E36: =INDEX('All Lots'!$AH$3:$AH$138,MATCH("14410 Villa Woods Pl",'All Lots'!$B$3:$B$138,0)) -> 3038302.4 | F36: =INDEX('All Lots'!$AH$3:$AH$138,MATCH("909 Rivas Canyon Rd",'All Lots'!$B$3:$B$138,0)) -> 4044556 | G36: =INDEX('All Lots'!$AH$3:$AH$138,MATCH("545 N Las Casas Ave",'All Lots'!$B$3:$B$138,0)) -> 1219565.5
A38: How to read it
A39: • Total cost = everything from buying the lot to selling the house, including loan costs, the realtor commission and LA's mansion tax (ULA) at sale.
A40: • Profit = sale price − total cost. 'Most we should pay' = the highest lot price that still earns the target margin (15%). Green = the lot works at asking; red = we'd need to negotiate down.
A41: • Construction is $700/sf fixed. Lots with city-approved plans (checked in LADBS 9/28/2026) use a 5% of asking price reserve instead of design and permit costs.
A42: • House size: city-approved plans where they exist; otherwise 110% of the old house or a rough zoning estimate an architect must confirm.
...

Sheet All Lots
A1: THE LOT | L1: THE HOUSE WE BUILD | Q1: COSTS | Y1: RETURNS (scenario chosen on Assumptions) | AC1: PROFIT IN EACH SCENARIO | AK1: BEHIND THE SCENES (math helpers)
A2: Rank | B2: Address | C2: Neighborhood | D2: Asking price | E2: Lot size (sf) | F2: Old house (sf) | G2: City-approved / claimed plans (sf) | H2: City-approved plans? | I2: Ocean view (MLS) | J2: Gated | K2: Notes | L2: New house size (sf) | M2: How sized | N2: Project length (yrs) | O2: Sale price per sf | P2: Sale price | Q2: Land | R2: Construction | S2: Design, permits & fees (or 5% reserve) | T2: Loan interest & points | U2: Property tax | V2: Commission & transfer tax | W2: Mansion tax (ULA) | X2: TOTAL COST | Y2: Profit | Z2: Margin (profit ÷ cost) | AA2: Most we should pay for the lot | AB2: Asking vs. most we should pay | AC2: Worst: sale $/sf | AD2: Worst: profit | AE2: Medium: sale $/sf | AF2: Medium: profit | AG2: Best: sale $/sf | AH2: Best: profit | AI2: Medium profit if build cost = A | AJ2: Medium profit if build cost = B | AK2: Nbhd code | AL2: Fast-path size | AM2: Build-to-zoning size | AN2: Profit: fast path | AO2: Profit: build to zoning | AP2: Loan amount
A3: 1 | B3: 14511 W Sunset Blvd | C3: Riviera | D3: 1099000 | E3: 7006 | F3: 2163 | H3: No | I3: No | J3: No | K3: private rd off Sunset; Tal 10/1: something feels off (access/entrance off Sunset), says it is a foreclosure; verify title and access | L3: =IF(AO3>AN3,AM3,AL3) -> 2802 | M3: =IF(AO3>AN3,"Zoning estimate",IF(H3="Yes","Approved plans",IF(G3>0,"Listing claim","110% old house"))) -> Zoning estimate | N3: =IF(AO3>AN3,IF(AM3>AL3,Assumptions!$B$22,Assumptions!$B$21),Assumptions!$B$21) -> 3 | O3: =(INDEX(Assumptions!$B$36:$B$48,MATCH(AK3,Assumptions!$A$36:$A$48,0))+IF(I3="Yes",Assumptions!$B$23,0)+IF(J3="Yes",Assumptions!$B$24,0))*(1+IF(UPPER(Assumptions!$B$31)="WORST",Assumptions!$B$28,IF(UPPER(Assumptions!$B$31)="BEST",Assumptions!$B$30,Assumptions!$B$29))) -> 2046 | P3: =L3*O3 -> 5732892 | Q3: =D3 -> 1099000 | R3: =L3*Assumptions!$B$4 -> 1961400 | S3: =IF(H3="Yes",Assumptions!$B$6*(D3),(L3)*Assumptions!$B$5) -> 210150 | T3: =AP3*(Assumptions!$B$8*N3*Assumptions!$B$9+Assumptions!$B$10) -> 414542.21 | U3: =Q3*Assumptions!$B$11*N3 -> 39564 | V3: =P3*(Assumptions!$B$12+Assumptions!$B$13) -> 232755.42 | W3: =P3*IF(P3>=Assumptions!$B$16,Assumptions!$B$17,IF(P3>=Assumptions!$B$14,Assumptions!$B$15,0)) -> 229315.68 | X3: =SUM(Q3:W3) -> 4186727.3 | Y3: =P3-X3 -> 1546164.7 | Z3: =IF(X3=0,0,Y3/X3) -> 0.3693015 | AA3: =MAX(0,(P3/(1+Assumptions!$B$27)-(L3*(Assumptions!$B$4+IF(H3="Yes",0,Assumptions!$B$5)))*(1+(Assumptions!$B$7*(Assumptions!$B$8*N3*Assumptions!$B$9+Assumptions!$B$10)))-P3*(Assumptions!$B$12+Assumptions!$B$13+IF(P3>=Assumptions!$B$16,Assumptions!$B$17,IF(P3>=Assumptions!$B$14,Assumptions!$B$15,0))))/((1+IF(H3="Yes",Assumptions!$B$6,0))*(1+(Assumptions!$B$7*(Assumptions!$B$8*N3*Assumptions!$B$9+Assumptions!$B$10)))+Assumptions!$B$11*N3)) -> 1785644.7 | AB3: =IF(AA3<=0,"no price works",D3/AA3) -> 0.61546397 | AC3: =(INDEX(Assumptions!$B$36:$B$48,MATCH(AK3,Assumptions!$A$36:$A$48,0))+IF(I3="Yes",Assumptions!$B$23,0)+IF(J3="Yes",Assumptions!$B$24,0))*(1+Assumptions!$B$28) -> 1860 | AD3: =(L3)*AC3-(((D3)+(L3)*Assumptions!$B$4+IF(H3="Yes",Assumptions!$B$6*(D3),(L3)*Assumptions!$B$5))*(1+Assumptions!$B$7*(Assumptions!$B$8*(N3)*Assumptions!$B$9+Assumptions!$B$10))+(D3)*Assumptions!$B$11*(N3)+(L3)*AC3*(Assumptions!$B$12+Assumptions!$B$13+IF((L3)*AC3>=Assumptions!$B$16,Assumptions!$B$17,IF((L3)*AC3>=Assumptions!$B$14,Assumptions!$B$15,0)))) -> 1275468 | AE3: =(INDEX(Assumptions!$B$36:$B$48,MATCH(AK3,Assumptions!$A$36:$A$48,0))+IF(I3="Yes",Assumptions!$B$23,0)+IF(J3="Yes",Assumptions!$B$24,0))*(1+Assumptions!$B$29) -> 2046 | AF3: =(L3)*AE3-(((D3)+(L3)*Assumptions!$B$4+IF(H3="Yes",Assumptions!$B$6*(D3),(L3)*Assumptions!$B$5))*(1+Assumptions!$B$7*(Assumptions!$B$8*(N3)*Assumptions!$B$9+Assumptions!$B$10))+(D3)*Assumptions!$B$11*(N3)+(L3)*AE3*(Assumptions!$B$12+Assumptions!$B$13+IF((L3)*AE3>=Assumptions!$B$16,Assumptions!$B$17,IF((L3)*AE3>=Assumptions!$B$14,Assumptions!$B$15,0)))) -> 1546164.7 | AG3: =(INDEX(Assumptions!$B$36:$B$48,MATCH(AK3,Assumptions!$A$36:$A$48,0))+IF(I3="Yes",Assumptions!$B$23,0)+IF(J3="Yes",Assumptions!$B$24,0))*(1+Assumptions!$B$30) -> 2232 | AH3: =(L3)*AG3-(((D3)+(L3)*Assumptions!$B$4+IF(H3="Yes",Assumptions!$B$6*(D3),(L3)*Assumptions!$B$5))*(1+Assumptions!$B$7*(Assumptions!$B$8*(N3)*Assumptions!$B$9+Assumptions!$B$10))+(D3)*Assumptions!$B$11*(N3)+(L3)*AG3*(Assumptions!$B$12+Assumptions!$B$13+IF((L3)*AG3>=Assumptions!$B$16,Assumptions!$B$17,IF((L3)*AG3>=Assumptions!$B$14,Assumptions!$B$15,0)))) -> 2025330.2 | AI3: =(L3)*AE3-(((D3)+(L3)*Assumptions!$B$25+IF(H3="Yes",Assumptions!$B$6*(D3),(L3)*Assumptions!$B$5))*(1+Assumptions!$B$7*(Assumptions!$B$8*(N3)*Assumptions!$B$9+Assumptions!$B$10))+(D3)*Assumptions!$B$11*(N3)+(L3)*AE3*(Assumptions!$B$12+Assumptions!$B$13+IF((L3)*AE3>=Assumptions!$B$16,Assumptions!$B$17,IF((L3)*AE3>=Assumptions!$B$14,Assumptions!$B$15,0)))) -> 1704022.4 | AJ3: =(L3)*AE3-(((D3)+(L3)*Assumptions!$B$26+IF(H3="Yes",Assumptions!$B$6*(D3),(L3)*Assumptions!$B$5))*(1+Assumptions!$B$7*(Assumptions!$B$8*(N3)*Assumptions!$B$9+Assumptions!$B$10))+(D3)*Assumptions!$B$11*(N3)+(L3)*AE3*(Assumptions!$B$12+Assumptions!$B$13+IF((L3)*AE3>=Assumptions!$B$16,Assumptions!$B$17,IF((L3)*AE3>=Assumptions!$B$14,Assumptions!$B$15,0)))) -> 1861880 | AK3: RIV | AL3: =IF(G3>0,G3,ROUND(F3*Assumptions!$B$18,0)) -> 2379 | AM3: =IF(H3="Yes",AL3,MAX(AL3,MIN(Assumptions!$B$20,ROUND(E3*Assumptions!$B$19,0)))) -> 2802 | AN3: =(AL3)*AE3-(((D3)+(AL3)*Assumptions!$B$4+IF(H3="Yes",Assumptions!$B$6*(D3),(AL3)*Assumptions!$B$5))*(1+Assumptions!$B$7*(Assumptions!$B$8*(Assumptions!$B$21)*Assumptions!$B$9+Assumptions!$B$10))+(D3)*Assumptions!$B$11*(Assumptions!$B$21)+(AL3)*AE3*(Assumptions!$B$12+Assumptions!$B$13+IF((AL3)*AE3>=Assumptions!$B$16,Assumptions!$B$17,IF((AL3)*AE3>=Assumptions!$B$14,Assumptions!$B$15,0)))) -> 1442491.1 | AO3: =(AM3)*AE3-(((D3)+(AM3)*Assumptions!$B$4+IF(H3="Yes",Assumptions!$B$6*(D3),(AM3)*Assumptions!$B$5))*(1+Assumptions!$B$7*(Assumptions!$B$8*(IF(AM3>AL3,Assumptions!$B$22,Assumptions!$B$21))*Assumptions!$B$9+Assumptions!$B$10))+(D3)*Assumptions!$B$11*(IF(AM3>AL3,Assumptions!$B$22,Assumptions!$B$21))+(AM3)*AE3*(Assumptions!$B$12+Assumptions!$B$13+IF((AM3)*AE3>=Assumptions!$B$16,Assumptions!$B$17,IF((AM3)*AE3>=Assumptions!$B$14,Assumptions!$B$15,0)))) -> 1546164.7 | AP3: =Assumptions!$B$7*(Q3+R3+S3) -> 2125857.5
A4: 2 | B4: 545 N Las Casas Ave | C4: Bluffs / El Medio | D4: 995000 | E4: 4382 | F4: 3014 | H4: No | I4: No | J4: No | K4: small lot | L4: =IF(AO4>AN4,AM4,AL4) -> 3315 | M4: =IF(AO4>AN4,"Zoning estimate",IF(H4="Yes","Approved plans",IF(G4>0,"Listing claim","110% old house"))) -> 110% old house | N4: =IF(AO4>AN4,IF(AM4>AL4,Assumptions!$B$22,Assumptions!$B$21),Assumptions!$B$21) -> 2 | O4: =(INDEX(Assumptions!$B$36:$B$48,MATCH(AK4,Assumptions!$A$36:$A$48,0))+IF(I4="Yes",Assumptions!$B$23,0)+IF(J4="Yes",Assumptions!$B$24,0))*(1+IF(UPPER(Assumptions!$B$31)="WORST",Assumptions!$B$28,IF(UPPER(Assumptions!$B$31)="BEST",Assumptions!$B$30,Assumptions!$B$29))) -> 1540 | P4: =L4*O4 -> 5105100 | Q4: =D4 -> 995000 | R4: =L4*Assumptions!$B$4 -> 2320500 | S4: =IF(H4="Yes",Assumptions!$B$6*(D4),(L4)*Assumptions!$B$5) -> 248625 | T4: =AP4*(Assumptions!$B$8*N4*Assumptions!$B$9+Assumptions!$B$10) -> 312751.97 | U4: =Q4*Assumptions!$B$11*N4 -> 23880 | V4: =P4*(Assumptions!$B$12+Assumptions!$B$13) -> 207267.06 | W4: =P4*IF(P4>=Assumptions!$B$16,Assumptions!$B$17,IF(P4>=Assumptions!$B$14,Assumptions!$B$15,0)) -> 0 | X4: =SUM(Q4:W4) -> 4108024 | Y4: =P4-X4 -> 997075.97 | Z4: =IF(X4=0,0,Y4/X4) -> 0.24271425 | AA4: =MAX(0,(P4/(1+Assumptions!$B$27)-(L4*(Assumptions!$B$4+IF(H4="Yes",0,Assumptions!$B$5)))*(1+(Assumptions!$B$7*(Assumptions!$B$8*N4*Assumptions!$B$9+Assumptions!$B$10)))-P4*(Assumptions!$B$12+Assumptions!$B$13+IF(P4>=Assumptions!$B$16,Assumptions!$B$17,IF(P4>=Assumptions!$B$14,Assumptions!$B$15,0))))/((1+IF(H4="Yes",Assumptions!$B$6,0))*(1+(Assumptions!$B$7*(Assumptions!$B$8*N4*Assumptions!$B$9+Assumptions!$B$10)))+Assumptions!$B$11*N4)) -> 1292902.7 | AB4: =IF(AA4<=0,"no price works",D4/AA4) -> 0.76958612 | AC4: =(INDEX(Assumptions!$B$36:$B$48,MATCH(AK4,Assumptions!$A$36:$A$48,0))+IF(I4="Yes",Assumptions!$B$23,0)+IF(J4="Yes",Assumptions!$B$24,0))*(1+Assumptions!$B$28) -> 1400 | AD4: =(L4)*AC4-(((D4)+(L4)*Assumptions!$B$4+IF(H4="Yes",Assumptions!$B$6*(D4),(L4)*Assumptions!$B$5))*(1+Assumptions!$B$7*(Assumptions!$B$8*(N4)*Assumptions!$B$9+Assumptions!$B$10))+(D4)*Assumptions!$B$11*(N4)+(L4)*AC4*(Assumptions!$B$12+Assumptions!$B$13+IF((L4)*AC4>=Assumptions!$B$16,Assumptions!$B$17,IF((L4)*AC4>=Assumptions!$B$14,Assumptions!$B$15,0)))) -> 551818.43 | AE4: =(INDEX(Assumptions!$B$36:$B$48,MATCH(AK4,Assumptions!$A$36:$A$48,0))+IF(I4="Yes",Assumptions!$B$23,0)+IF(J4="Yes",Assumptions!$B$24,0))*(1+Assumptions!$B$29) -> 1540 | AF4: =(L4)*AE4-(((D4)+(L4)*Assumptions!$B$4+IF(H4="Yes",Assumptions!$B$6*(D4),(L4)*Assumptions!$B$5))*(1+Assumptions!$B$7*(Assumptions!$B$8*(N4)*Assumptions!$B$9+Assumptions!$B$10))+(D4)*Assumptions!$B$11*(N4)+(L4)*AE4*(Assumptions!$B$12+Assumptions!$B$13+IF((L4)*AE4>=Assumptions!$B$16,Assumptions!$B$17,IF((L4)*AE4>=Assumptions!$B$14,Assumptions!$B$15,0)))) -> 997075.97 | AG4: =(INDEX(Assumptions!$B$36:$B$48,MATCH(AK4,Assumptions!$A$36:$A$48,0))+IF(I4="Yes",Assumptions!$B$23,0)+IF(J4="Yes",Assumptions!$B$24,0))*(1+Assumptions!$B$30) -> 1680 | AH4: =(L4)*AG4-(((D4)+(L4)*Assumptions!$B$4+IF(H4="Yes",Assumptions!$B$6*(D4),(L4)*Assumptions!$B$5))*(1+Assumptions!$B$7*(Assumptions!$B$8*(N4)*Assumptions!$B$9+Assumptions!$B$10))+(D4)*Assumptions!$B$11*(N4)+(L4)*AG4*(Assumptions!$B$12+Assumptions!$B$13+IF((L4)*AG4>=Assumptions!$B$16,Assumptions!$B$17,IF((L4)*AG4>=Assumptions!$B$14,Assumptions!$B$15,0)))) -> 1219565.5 | AI4: =(L4)*AE4-(((D4)+(L4)*Assumptions!$B$25+IF(H4="Yes",Assumptions!$B$6*(D4),(L4)*Assumptions!$B$5))*(1+Assumptions!$B$7*(Assumptions!$B$8*(N4)*Assumptions!$B$9+Assumptions!$B$10))+(D4)*Assumptions!$B$11*(N4)+(L4)*AE4*(Assumptions!$B$12+Assumptions!$B$13+IF((L4)*AE4>=Assumptions!$B$16,Assumptions!$B$17,IF((L4)*AE4>=Assumptions!$B$14,Assumptions!$B$15,0)))) -> 1177370.5 | AJ4: =(L4)*AE4-(((D4)+(L4)*Assumptions!$B$26+IF(H4="Yes",Assumptions!$B$6*(D4),(L4)*Assumptions!$B$5))*(1+Assumptions!$B$7*(Assumptions!$B$8*(N4)*Assumptions!$B$9+Assumptions!$B$10))+(D4)*Assumptions!$B$11*(N4)+(L4)*AE4*(Assumptions!$B$12+Assumptions!$B$13+IF((L4)*AE4>=Assumptions!$B$16,Assumptions!$B$17,IF((L4)*AE4>=Assumptions!$B$14,Assumptions!$B$15,0)))) -> 1357665.1 | AK4: BLUFF | AL4: =IF(G4>0,G4,ROUND(F4*Assumptions!$B$18,0)) -> 3315 | AM4: =IF(H4="Yes",AL4,MAX(AL4,MIN(Assumptions!$B$20,ROUND(E4*Assumptions!$B$19,0)))) -> 3315 | AN4: =(AL4)*AE4-(((D4)+(AL4)*Assumptions!$B$4+IF(H4="Yes",Assumptions!$B$6*(D4),(AL4)*Assumptions!$B$5))*(1+Assumptions!$B$7*(Assumptions!$B$8*(Assumptions!$B$21)*Assumptions!$B$9+Assumptions!$B$10))+(D4)*Assumptions!$B$11*(Assumptions!$B$21)+(AL4)*AE4*(Assumptions!$B$12+Assumptions!$B$13+IF((AL4)*AE4>=Assumptions!$B$16,Assumptions!$B$17,IF((AL4)*AE4>=Assumptions!$B$14,Assumptions!$B$15,0)))) -> 997075.97 | AO4: =(AM4)*AE4-(((D4)+(AM4)*Assumptions!$B$4+IF(H4="Yes",Assumptions!$B$6*(D4),(AM4)*Assumptions!$B$5))*(1+Assumptions!$B$7*(Assumptions!$B$8*(IF(AM4>AL4,Assumptions!$B$22,Assumptions!$B$21))*Assumptions!$B$9+Assumptions!$B$10))+(D4)*Assumptions!$B$11*(IF(AM4>AL4,Assumptions!$B$22,Assumptions!$B$21))+(AM4)*AE4*(Assumptions!$B$12+Assumptions!$B$13+IF((AM4)*AE4>=Assumptions!$B$16,Assumptions!$B$17,IF((AM4)*AE4>=Assumptions!$B$14,Assumptions!$B$15,0)))) -> 997075.97 | AP4: =Assumptions!$B$7*(Q4+R4+S4) -> 2316681.2
A5: 3 | B5: 711 Chapala Dr | C5: Huntington | D5: 4375000 | E5: 8008 | F5: 3383 | G5: 7504 | H5: Yes | I5: No | J5: No | K5: LADBS: plan check approved 7/8/26, 7,504 sf (not advertised as RTI) | L5: =IF(AO5>AN5,AM5,AL5) -> 7504 | M5: =IF(AO5>AN5,"Zoning estimate",IF(H5="Yes","Approved plans",IF(G5>0,"Listing claim","110% old house"))) -> Approved plans | N5: =IF(AO5>AN5,IF(AM5>AL5,Assumptions!$B$22,Assumptions!$B$21),Assumptions!$B$21) -> 2 | O5: =(INDEX(Assumptions!$B$36:$B$48,MATCH(AK5,Assumptions!$A$36:$A$48,0))+IF(I5="Yes",Assumptions!$B$23,0)+IF(J5="Yes",Assumptions!$B$24,0))*(1+IF(UPPER(Assumptions!$B$31)="WORST",Assumptions!$B$28,IF(UPPER(Assumptions!$B$31)="BEST",Assumptions!$B$30,Assumptions!$B$29))) -> 2035 | P5: =L5*O5 -> 15270640 | Q5: =D5 -> 4375000 | R5: =L5*Assumptions!$B$4 -> 5252800 | S5: =IF(H5="Yes",Assumptions!$B$6*(D5),(L5)*Assumptions!$B$5) -> 218750 | T5: =AP5*(Assumptions!$B$8*N5*Assumptions!$B$9+Assumptions!$B$10) -> 864034.76 | U5: =Q5*Assumptions!$B$11*N5 -> 105000 | V5: =P5*(Assumptions!$B$12+Assumptions!$B$13) -> 619987.98 | W5: =P5*IF(P5>=Assumptions!$B$16,Assumptions!$B$17,IF(P5>=Assumptions!$B$14,Assumptions!$B$15,0)) -> 839885.2 | X5: =SUM(Q5:W5) -> 12275458 | Y5: =P5-X5 -> 2995182.1 | Z5: =IF(X5=0,0,Y5/X5) -> 0.24399758 | AA5: =MAX(0,(P5/(1+Assumptions!$B$27)-(L5*(Assumptions!$B$4+IF(H5="Yes",0,Assumptions!$B$5)))*(1+(Assumptions!$B$7*(Assumptions!$B$8*N5*Assumptions!$B$9+Assumptions!$B$10)))-P5*(Assumptions!$B$12+Assumptions!$B$13+IF(P5>=Assumptions!$B$16,Assumptions!$B$17,IF(P5>=Assumptions!$B$14,Assumptions!$B$15,0))))/((1+IF(H5="Yes",Assumptions!$B$6,0))*(1+(Assumptions!$B$7*(Assumptions!$B$8*N5*Assumptions!$B$9+Assumptions!$B$10)))+Assumptions!$B$11*N5)) -> 5235412.6 | AB5: =IF(AA5<=0,"no price works",D5/AA5) -> 0.83565524 | AC5: =(INDEX(Assumptions!$B$36:$B$48,MATCH(AK5,Assumptions!$A$36:$A$48,0))+IF(I5="Yes",Assumptions!$B$23,0)+IF(J5="Yes",Assumptions!$B$24,0))*(1+Assumptions!$B$28) -> 1850 | AD5: =(L5)*AC5-(((D5)+(L5)*Assumptions!$B$4+IF(H5="Yes",Assumptions!$B$6*(D5),(L5)*Assumptions!$B$5))*(1+Assumptions!$B$7*(Assumptions!$B$8*(N5)*Assumptions!$B$9+Assumptions!$B$10))+(D5)*Assumptions!$B$11*(N5)+(L5)*AC5*(Assumptions!$B$12+Assumptions!$B$13+IF((L5)*AC5>=Assumptions!$B$16,Assumptions!$B$17,IF((L5)*AC5>=Assumptions!$B$14,Assumptions!$B$15,0)))) -> 1739657.8 | AE5: =(INDEX(Assumptions!$B$36:$B$48,MATCH(AK5,Assumptions!$A$36:$A$48,0))+IF(I5="Yes",Assumptions!$B$23,0)+IF(J5="Yes",Assumptions!$B$24,0))*(1+Assumptions!$B$29) -> 2035 | AF5: =(L5)*AE5-(((D5)+(L5)*Assumptions!$B$4+IF(H5="Yes",Assumptions!$B$6*(D5),(L5)*Assumptions!$B$5))*(1+Assumptions!$B$7*(Assumptions!$B$8*(N5)*Assumptions!$B$9+Assumptions!$B$10))+(D5)*Assumptions!$B$11*(N5)+(L5)*AE5*(Assumptions!$B$12+Assumptions!$B$13+IF((L5)*AE5>=Assumptions!$B$16,Assumptions!$B$17,IF((L5)*AE5>=Assumptions!$B$14,Assumptions!$B$15,0)))) -> 2995182.1 | AG5: =(INDEX(Assumptions!$B$36:$B$48,MATCH(AK5,Assumptions!$A$36:$A$48,0))+IF(I5="Yes",Assumptions!$B$23,0)+IF(J5="Yes",Assumptions!$B$24,0))*(1+Assumptions!$B$30) -> 2220 | AH5: =(L5)*AG5-(((D5)+(L5)*Assumptions!$B$4+IF(H5="Yes",Assumptions!$B$6*(D5),(L5)*Assumptions!$B$5))*(1+Assumptions!$B$7*(Assumptions!$B$8*(N5)*Assumptions!$B$9+Assumptions!$B$10))+(D5)*Assumptions!$B$11*(N5)+(L5)*AG5*(Assumptions!$B$12+Assumptions!$B$13+IF((L5)*AG5>=Assumptions!$B$16,Assumptions!$B$17,IF((L5)*AG5>=Assumptions!$B$14,Assumptions!$B$15,0)))) -> 4250706.3 | AI5: =(L5)*AE5-(((D5)+(L5)*Assumptions!$B$25+IF(H5="Yes",Assumptions!$B$6*(D5),(L5)*Assumptions!$B$5))*(1+Assumptions!$B$7*(Assumptions!$B$8*(N5)*Assumptions!$B$9+Assumptions!$B$10))+(D5)*Assumptions!$B$11*(N5)+(L5)*AE5*(Assumptions!$B$12+Assumptions!$B$13+IF((L5)*AE5>=Assumptions!$B$16,Assumptions!$B$17,IF((L5)*AE5>=Assumptions!$B$14,Assumptions!$B$15,0)))) -> 3403305.9 | AJ5: =(L5)*AE5-(((D5)+(L5)*Assumptions!$B$26+IF(H5="Yes",Assumptions!$B$6*(D5),(L5)*Assumptions!$B$5))*(1+Assumptions!$B$7*(Assumptions!$B$8*(N5)*Assumptions!$B$9+Assumptions!$B$10))+(D5)*Assumptions!$B$11*(N5)+(L5)*AE5*(Assumptions!$B$12+Assumptions!$B$13+IF((L5)*AE5>=Assumptions!$B$16,Assumptions!$B$17,IF((L5)*AE5>=Assumptions!$B$14,Assumptions!$B$15,0)))) -> 3811429.7 | AK5: HUNT | AL5: =IF(G5>0,G5,ROUND(F5*Assumptions!$B$18,0)) -> 7504 | AM5: =IF(H5="Yes",AL5,MAX(AL5,MIN(Assumptions!$B$20,ROUND(E5*Assumptions!$B$19,0)))) -> 7504 | AN5: =(AL5)*AE5-(((D5)+(AL5)*Assumptions!$B$4+IF(H5="Yes",Assumptions!$B$6*(D5),(AL5)*Assumptions!$B$5))*(1+Assumptions!$B$7*(Assumptions!$B$8*(Assumptions!$B$21)*Assumptions!$B$9+Assumptions!$B$10))+(D5)*Assumptions!$B$11*(Assumptions!$B$21)+(AL5)*AE5*(Assumptions!$B$12+Assumptions!$B$13+IF((AL5)*AE5>=Assumptions!$B$16,Assumptions!$B$17,IF((AL5)*AE5>=Assumptions!$B$14,Assumptions!$B$15,0)))) -> 2995182.1 | AO5: =(AM5)*AE5-(((D5)+(AM5)*Assumptions!$B$4+IF(H5="Yes",Assumptions!$B$6*(D5),(AM5)*Assumptions!$B$5))*(1+Assumptions!$B$7*(Assumptions!$B$8*(IF(AM5>AL5,Assumptions!$B$22,Assumptions!$B$21))*Assumptions!$B$9+Assumptions!$B$10))+(D5)*Assumptions!$B$11*(IF(AM5>AL5,Assumptions!$B$22,Assumptions!$B$21))+(AM5)*AE5*(Assumptions!$B$12+Assumptions!$B$13+IF((AM5)*AE5>=Assumptions!$B$16,Assumptions!$B$17,IF((AM5)*AE5>=Assumptions!$B$14,Assumptions!$B$15,0)))) -> 2995182.1 | AP5: =Assumptions!$B$7*(Q5+R5+S5) -> 6400257.5
A6: 4 | B6: 14410 Villa Woods Pl | C6: Riviera | D6: 2795000 | E6: 13724 | F6: 4219 | H6: No | I6: No | J6: No | K6: pool remains | L6: =IF(AO6>AN6,AM6,AL6) -> 5490 | M6: =IF(AO6>AN6,"Zoning estimate",IF(H6="Yes","Approved plans",IF(G6>0,"Listing claim","110% old house"))) -> Zoning estimate | N6: =IF(AO6>AN6,IF(AM6>AL6,Assumptions!$B$22,Assumptions!$B$21),Assumptions!$B$21) -> 3 | O6: =(INDEX(Assumptions!$B$36:$B$48,MATCH(AK6,Assumptions!$A$36:$A$48,0))+IF(I6="Yes",Assumptions!$B$23,0)+IF(J6="Yes",Assumptions!$B$24,0))*(1+IF(UPPER(Assumptions!$B$31)="WORST",Assumptions!$B$28,IF(UPPER(Assumptions!$B$31)="BEST",Assumptions!$B$30,Assumptions!$B$29))) -> 2046 | P6: =L6*O6 -> 11232540 | Q6: =D6 -> 2795000 | R6: =L6*Assumptions!$B$4 -> 3843000 | S6: =IF(H6="Yes",Assumptions!$B$6*(D6),(L6)*Assumptions!$B$5) -> 411750 | T6: =AP6*(Assumptions!$B$8*N6*Assumptions!$B$9+Assumptions!$B$10) -> 893555.81 | U6: =Q6*Assumptions!$B$11*N6 -> 100620 | V6: =P6*(Assumptions!$B$12+Assumptions!$B$13) -> 456041.12 | W6: =P6*IF(P6>=Assumptions!$B$16,Assumptions!$B$17,IF(P6>=Assumptions!$B$14,Assumptions!$B$15,0)) -> 617789.7 | X6: =SUM(Q6:W6) -> 9117756.6 | Y6: =P6-X6 -> 2114783.4 | Z6: =IF(X6=0,0,Y6/X6) -> 0.23194119 | AA6: =MAX(0,(P6/(1+Assumptions!$B$27)-(L6*(Assumptions!$B$4+IF(H6="Yes",0,Assumptions!$B$5)))*(1+(Assumptions!$B$7*(Assumptions!$B$8*N6*Assumptions!$B$9+Assumptions!$B$10)))-P6*(Assumptions!$B$12+Assumptions!$B$13+IF(P6>=Assumptions!$B$16,Assumptions!$B$17,IF(P6>=Assumptions!$B$14,Assumptions!$B$15,0))))/((1+IF(H6="Yes",Assumptions!$B$6,0))*(1+(Assumptions!$B$7*(Assumptions!$B$8*N6*Assumptions!$B$9+Assumptions!$B$10)))+Assumptions!$B$11*N6)) -> 3353735.3 | AB6: =IF(AA6<=0,"no price works",D6/AA6) -> 0.83339911 | AC6: =(INDEX(Assumptions!$B$36:$B$48,MATCH(AK6,Assumptions!$A$36:$A$48,0))+IF(I6="Yes",Assumptions!$B$23,0)+IF(J6="Yes",Assumptions!$B$24,0))*(1+Assumptions!$B$28) -> 1860 | AD6: =(L6)*AC6-(((D6)+(L6)*Assumptions!$B$4+IF(H6="Yes",Assumptions!$B$6*(D6),(L6)*Assumptions!$B$5))*(1+Assumptions!$B$7*(Assumptions!$B$8*(N6)*Assumptions!$B$9+Assumptions!$B$10))+(D6)*Assumptions!$B$11*(N6)+(L6)*AC6*(Assumptions!$B$12+Assumptions!$B$13+IF((L6)*AC6>=Assumptions!$B$16,Assumptions!$B$17,IF((L6)*AC6>=Assumptions!$B$14,Assumptions!$B$15,0)))) -> 1344435.3 | AE6: =(INDEX(Assumptions!$B$36:$B$48,MATCH(AK6,Assumptions!$A$36:$A$48,0))+IF(I6="Yes",Assumptions!$B$23,0)+IF(J6="Yes",Assumptions!$B$24,0))*(1+Assumptions!$B$29) -> 2046 | AF6: =(L6)*AE6-(((D6)+(L6)*Assumptions!$B$4+IF(H6="Yes",Assumptions!$B$6*(D6),(L6)*Assumptions!$B$5))*(1+Assumptions!$B$7*(Assumptions!$B$8*(N6)*Assumptions!$B$9+Assumptions!$B$10))+(D6)*Assumptions!$B$11*(N6)+(L6)*AE6*(Assumptions!$B$12+Assumptions!$B$13+IF((L6)*AE6>=Assumptions!$B$16,Assumptions!$B$17,IF((L6)*AE6>=Assumptions!$B$14,Assumptions!$B$15,0)))) -> 2114783.4 | AG6: =(INDEX(Assumptions!$B$36:$B$48,MATCH(AK6,Assumptions!$A$36:$A$48,0))+IF(I6="Yes",Assumptions!$B$23,0)+IF(J6="Yes",Assumptions!$B$24,0))*(1+Assumptions!$B$30) -> 2232 | AH6: =(L6)*AG6-(((D6)+(L6)*Assumptions!$B$4+IF(H6="Yes",Assumptions!$B$6*(D6),(L6)*Assumptions!$B$5))*(1+Assumptions!$B$7*(Assumptions!$B$8*(N6)*Assumptions!$B$9+Assumptions!$B$10))+(D6)*Assumptions!$B$11*(N6)+(L6)*AG6*(Assumptions!$B$12+Assumptions!$B$13+IF((L6)*AG6>=Assumptions!$B$16,Assumptions!$B$17,IF((L6)*AG6>=Assumptions!$B$14,Assumptions!$B$15,0)))) -> 3038302.4 | AI6: =(L6)*AE6-(((D6)+(L6)*Assumptions!$B$25+IF(H6="Yes",Assumptions!$B$6*(D6),(L6)*Assumptions!$B$5))*(1+Assumptions!$B$7*(Assumptions!$B$8*(N6)*Assumptions!$B$9+Assumptions!$B$10))+(D6)*Assumptions!$B$11*(N6)+(L6)*AE6*(Assumptions!$B$12+Assumptions!$B$13+IF((L6)*AE6>=Assumptions!$B$16,Assumptions!$B$17,IF((L6)*AE6>=Assumptions!$B$14,Assumptions!$B$15,0)))) -> 2424076.2 | AJ6: =(L6)*AE6-(((D6)+(L6)*Assumptions!$B$26+IF(H6="Yes",Assumptions!$B$6*(D6),(L6)*Assumptions!$B$5))*(1+Assumptions!$B$7*(Assumptions!$B$8*(N6)*Assumptions!$B$9+Assumptions!$B$10))+(D6)*Assumptions!$B$11*(N6)+(L6)*AE6*(Assumptions!$B$12+Assumptions!$B$13+IF((L6)*AE6>=Assumptions!$B$16,Assumptions!$B$17,IF((L6)*AE6>=Assumptions!$B$14,Assumptions!$B$15,0)))) -> 2733369.1 | AK6: RIV | AL6: =IF(G6>0,G6,ROUND(F6*Assumptions!$B$18,0)) -> 4641 | AM6: =IF(H6="Yes",AL6,MAX(AL6,MIN(Assumptions!$B$20,ROUND(E6*Assumptions!$B$19,0)))) -> 5490 | AN6: =(AL6)*AE6-(((D6)+(AL6)*Assumptions!$B$4+IF(H6="Yes",Assumptions!$B$6*(D6),(AL6)*Assumptions!$B$5))*(1+Assumptions!$B$7*(Assumptions!$B$8*(Assumptions!$B$21)*Assumptions!$B$9+Assumptions!$B$10))+(D6)*Assumptions!$B$11*(Assumptions!$B$21)+(AL6)*AE6*(Assumptions!$B$12+Assumptions!$B$13+IF((AL6)*AE6>=Assumptions!$B$16,Assumptions!$B$17,IF((AL6)*AE6>=Assumptions!$B$14,Assumptions!$B$15,0)))) -> 1710416.6 | AO6: =(AM6)*AE6-(((D6)+(AM6)*Assumptions!$B$4+IF(H6="Yes",Assumptions!$B$6*(D6),(AM6)*Assumptions!$B$5))*(1+Assumptions!$B$7*(Assumptions!$B$8*(IF(AM6>AL6,Assumptions!$B$22,Assumptions!$B$21))*Assumptions!$B$9+Assumptions!$B$10))+(D6)*Assumptions!$B$11*(IF(AM6>AL6,Assumptions!$B$22,Assumptions!$B$21))+(AM6)*AE6*(Assumptions!$B$12+Assumptions!$B$13+IF((AM6)*AE6>=Assumptions!$B$16,Assumptions!$B$17,IF((AM6)*AE6>=Assumptions!$B$14,Assumptions!$B$15,0)))) -> 2114783.4 | AP6: =Assumptions!$B$7*(Q6+R6+S6) -> 4582337.5
A7: 5 | B7: 16150 Northfield St | C7: Bluffs / El Medio | D7: 1395000 | E7: 5556 | F7: 1302 | G7: 4270 | H7: Yes | I7: No | J7: No | K7: LADBS: plan check approved 6/25/26, 4,270 sf (listing 5,200); flip | L7: =IF(AO7>AN7,AM7,AL7) -> 4270 | M7: =IF(AO7>AN7,"Zoning estimate",IF(H7="Yes","Approved plans",IF(G7>0,"Listing claim","110% old house"))) -> Approved plans | N7: =IF(AO7>AN7,IF(AM7>AL7,Assumptions!$B$22,Assumptions!$B$21),Assumptions!$B$21) -> 2 | O7: =(INDEX(Assumptions!$B$36:$B$48,MATCH(AK7,Assumptions!$A$36:$A$48,0))+IF(I7="Yes",Assumptions!$B$23,0)+IF(J7="Yes",Assumptions!$B$24,0))*(1+IF(UPPER(Assumptions!$B$31)="WORST",Assumptions!$B$28,IF(UPPER(Assumptions!$B$31)="BEST",Assumptions!$B$30,Assumptions!$B$29))) -> 1540 | P7: =L7*O7 -> 6575800 | Q7: =D7 -> 1395000 | R7: =L7*Assumptions!$B$4 -> 2989000 | S7: =IF(H7="Yes",Assumptions!$B$6*(D7),(L7)*Assumptions!$B$5) -> 69750 | T7: =AP7*(Assumptions!$B$8*N7*Assumptions!$B$9+Assumptions!$B$10) -> 390816.56 | U7: =Q7*Assumptions!$B$11*N7 -> 33480 | V7: =P7*(Assumptions!$B$12+Assumptions!$B$13) -> 266977.48 | W7: =P7*IF(P7>=Assumptions!$B$16,Assumptions!$B$17,IF(P7>=Assumptions!$B$14,Assumptions!$B$15,0)) -> 263032 | X7: =SUM(Q7:W7) -> 5408056 | Y7: =P7-X7 -> 1167744 | Z7: =IF(X7=0,0,Y7/X7) -> 0.21592675 | AA7: =MAX(0,(P7/(1+Assumptions!$B$27)-(L7*(Assumptions!$B$4+IF(H7="Yes",0,Assumptions!$B$5)))*(1+(Assumptions!$B$7*(Assumptions!$B$8*N7*Assumptions!$B$9+Assumptions!$B$10)))-P7*(Assumptions!$B$12+Assumptions!$B$13+IF(P7>=Assumptions!$B$16,Assumptions!$B$17,IF(P7>=Assumptions!$B$14,Assumptions!$B$15,0))))/((1+IF(H7="Yes",Assumptions!$B$6,0))*(1+(Assumptions!$B$7*(Assumptions!$B$8*N7*Assumptions!$B$9+Assumptions!$B$10)))+Assumptions!$B$11*N7)) -> 1660861.4 | AB7: =IF(AA7<=0,"no price works",D7/AA7) -> 0.83992561 | AC7: =(INDEX(Assumptions!$B$36:$B$48,MATCH(AK7,Assumptions!$A$36:$A$48,0))+IF(I7="Yes",Assumptions!$B$23,0)+IF(J7="Yes",Assumptions!$B$24,0))*(1+Assumptions!$B$28) -> 1400 | AD7: =(L7)*AC7-(((D7)+(L7)*Assumptions!$B$4+IF(H7="Yes",Assumptions!$B$6*(D7),(L7)*Assumptions!$B$5))*(1+Assumptions!$B$7*(Assumptions!$B$8*(N7)*Assumptions!$B$9+Assumptions!$B$10))+(D7)*Assumptions!$B$11*(N7)+(L7)*AC7*(Assumptions!$B$12+Assumptions!$B$13+IF((L7)*AC7>=Assumptions!$B$16,Assumptions!$B$17,IF((L7)*AC7>=Assumptions!$B$14,Assumptions!$B$15,0)))) -> 618126.64 | AE7: =(INDEX(Assumptions!$B$36:$B$48,MATCH(AK7,Assumptions!$A$36:$A$48,0))+IF(I7="Yes",Assumptions!$B$23,0)+IF(J7="Yes",Assumptions!$B$24,0))*(1+Assumptions!$B$29) -> 1540 | AF7: =(L7)*AE7-(((D7)+(L7)*Assumptions!$B$4+IF(H7="Yes",Assumptions!$B$6*(D7),(L7)*Assumptions!$B$5))*(1+Assumptions!$B$7*(Assumptions!$B$8*(N7)*Assumptions!$B$9+Assumptions!$B$10))+(D7)*Assumptions!$B$11*(N7)+(L7)*AE7*(Assumptions!$B$12+Assumptions!$B$13+IF((L7)*AE7>=Assumptions!$B$16,Assumptions!$B$17,IF((L7)*AE7>=Assumptions!$B$14,Assumptions!$B$15,0)))) -> 1167744 | AG7: =(INDEX(Assumptions!$B$36:$B$48,MATCH(AK7,Assumptions!$A$36:$A$48,0))+IF(I7="Yes",Assumptions!$B$23,0)+IF(J7="Yes",Assumptions!$B$24,0))*(1+Assumptions!$B$30) -> 1680 | AH7: =(L7)*AG7-(((D7)+(L7)*Assumptions!$B$4+IF(H7="Yes",Assumptions!$B$6*(D7),(L7)*Assumptions!$B$5))*(1+Assumptions!$B$7*(Assumptions!$B$8*(N7)*Assumptions!$B$9+Assumptions!$B$10))+(D7)*Assumptions!$B$11*(N7)+(L7)*AG7*(Assumptions!$B$12+Assumptions!$B$13+IF((L7)*AG7>=Assumptions!$B$16,Assumptions!$B$17,IF((L7)*AG7>=Assumptions!$B$14,Assumptions!$B$15,0)))) -> 1717361.3 | AI7: =(L7)*AE7-(((D7)+(L7)*Assumptions!$B$25+IF(H7="Yes",Assumptions!$B$6*(D7),(L7)*Assumptions!$B$5))*(1+Assumptions!$B$7*(Assumptions!$B$8*(N7)*Assumptions!$B$9+Assumptions!$B$10))+(D7)*Assumptions!$B$11*(N7)+(L7)*AE7*(Assumptions!$B$12+Assumptions!$B$13+IF((L7)*AE7>=Assumptions!$B$16,Assumptions!$B$17,IF((L7)*AE7>=Assumptions!$B$14,Assumptions!$B$15,0)))) -> 1399978.6 | AJ7: =(L7)*AE7-(((D7)+(L7)*Assumptions!$B$26+IF(H7="Yes",Assumptions!$B$6*(D7),(L7)*Assumptions!$B$5))*(1+Assumptions!$B$7*(Assumptions!$B$8*(N7)*Assumptions!$B$9+Assumptions!$B$10))+(D7)*Assumptions!$B$11*(N7)+(L7)*AE7*(Assumptions!$B$12+Assumptions!$B$13+IF((L7)*AE7>=Assumptions!$B$16,Assumptions!$B$17,IF((L7)*AE7>=Assumptions!$B$14,Assumptions!$B$15,0)))) -> 1632213.2 | AK7: BLUFF | AL7: =IF(G7>0,G7,ROUND(F7*Assumptions!$B$18,0)) -> 4270 | AM7: =IF(H7="Yes",AL7,MAX(AL7,MIN(Assumptions!$B$20,ROUND(E7*Assumptions!$B$19,0)))) -> 4270 | AN7: =(AL7)*AE7-(((D7)+(AL7)*Assumptions!$B$4+IF(H7="Yes",Assumptions!$B$6*(D7),(AL7)*Assumptions!$B$5))*(1+Assumptions!$B$7*(Assumptions!$B$8*(Assumptions!$B$21)*Assumptions!$B$9+Assumptions!$B$10))+(D7)*Assumptions!$B$11*(Assumptions!$B$21)+(AL7)*AE7*(Assumptions!$B$12+Assumptions!$B$13+IF((AL7)*AE7>=Assumptions!$B$16,Assumptions!$B$17,IF((AL7)*AE7>=Assumptions!$B$14,Assumptions!$B$15,0)))) -> 1167744 | AO7: =(AM7)*AE7-(((D7)+(AM7)*Assumptions!$B$4+IF(H7="Yes",Assumptions!$B$6*(D7),(AM7)*Assumptions!$B$5))*(1+Assumptions!$B$7*(Assumptions!$B$8*(IF(AM7>AL7,Assumptions!$B$22,Assumptions!$B$21))*Assumptions!$B$9+Assumptions!$B$10))+(D7)*Assumptions!$B$11*(IF(AM7>AL7,Assumptions!$B$22,Assumptions!$B$21))+(AM7)*AE7*(Assumptions!$B$12+Assumptions!$B$13+IF((AM7)*AE7>=Assumptions!$B$16,Assumptions!$B$17,IF((AM7)*AE7>=Assumptions!$B$14,Assumptions!$B$15,0)))) -> 1167744 | AP7: =Assumptions!$B$7*(Q7+R7+S7) -> 2894937.5
A8: 6 | B8: 909 Rivas Canyon Rd | C8: Riviera | D8: 3750000 | E8: 18344 | F8: 3254 | H8: No | I8: No | J8: No | L8: =IF(AO8>AN8,AM8,AL8) -> 7338 | M8: =IF(AO8>AN8,"Zoning estimate",IF(H8="Yes","Approved plans",IF(G8>0,"Listing claim","110% old house"))) -> Zoning estimate | N8: =IF(AO8>AN8,IF(AM8>AL8,Assumptions!$B$22,Assumptions!$B$21),Assumptions!$B$21) -> 3 | O8: =(INDEX(Assumptions!$B$36:$B$48,MATCH(AK8,Assumptions!$A$36:$A$48,0))+IF(I8="Yes",Assumptions!$B$23,0)+IF(J8="Yes",Assumptions!$B$24,0))*(1+IF(UPPER(Assumptions!$B$31)="WORST",Assumptions!$B$28,IF(UPPER(Assumptions!$B$31)="BEST",Assumptions!$B$30,Assumptions!$B$29))) -> 2046 | P8: =L8*O8 -> 15013548 | Q8: =D8 -> 3750000 | R8: =L8*Assumptions!$B$4 -> 5136600 | S8: =IF(H8="Yes",Assumptions!$B$6*(D8),(L8)*Assumptions!$B$5) -> 550350 | T8: =AP8*(Assumptions!$B$8*N8*Assumptions!$B$9+Assumptions!$B$10) -> 1196133.4 | U8: =Q8*Assumptions!$B$11*N8 -> 135000 | V8: =P8*(Assumptions!$B$12+Assumptions!$B$13) -> 609550.05 | W8: =P8*IF(P8>=Assumptions!$B$16,Assumptions!$B$17,IF(P8>=Assumptions!$B$14,Assumptions!$B$15,0)) -> 825745.14 | X8: =SUM(Q8:W8) -> 12203379 | Y8: =P8-X8 -> 2810169.4 | Z8: =IF(X8=0,0,Y8/X8) -> 0.23027798 | AA8: =MAX(0,(P8/(1+Assumptions!$B$27)-(L8*(Assumptions!$B$4+IF(H8="Yes",0,Assumptions!$B$5)))*(1+(Assumptions!$B$7*(Assumptions!$B$8*N8*Assumptions!$B$9+Assumptions!$B$10)))-P8*(Assumptions!$B$12+Assumptions!$B$13+IF(P8>=Assumptions!$B$16,Assumptions!$B$17,IF(P8>=Assumptions!$B$14,Assumptions!$B$15,0))))/((1+IF(H8="Yes",Assumptions!$B$6,0))*(1+(Assumptions!$B$7*(Assumptions!$B$8*N8*Assumptions!$B$9+Assumptions!$B$10)))+Assumptions!$B$11*N8)) -> 4482642.9 | AB8: =IF(AA8<=0,"no price works",D8/AA8) -> 0.83656006 | AC8: =(INDEX(Assumptions!$B$36:$B$48,MATCH(AK8,Assumptions!$A$36:$A$48,0))+IF(I8="Yes",Assumptions!$B$23,0)+IF(J8="Yes",Assumptions!$B$24,0))*(1+Assumptions!$B$28) -> 1860 | AD8: =(L8)*AC8-(((D8)+(L8)*Assumptions!$B$4+IF(H8="Yes",Assumptions!$B$6*(D8),(L8)*Assumptions!$B$5))*(1+Assumptions!$B$7*(Assumptions!$B$8*(N8)*Assumptions!$B$9+Assumptions!$B$10))+(D8)*Assumptions!$B$11*(N8)+(L8)*AC8*(Assumptions!$B$12+Assumptions!$B$13+IF((L8)*AC8>=Assumptions!$B$16,Assumptions!$B$17,IF((L8)*AC8>=Assumptions!$B$14,Assumptions!$B$15,0)))) -> 1575782.8 | AE8: =(INDEX(Assumptions!$B$36:$B$48,MATCH(AK8,Assumptions!$A$36:$A$48,0))+IF(I8="Yes",Assumptions!$B$23,0)+IF(J8="Yes",Assumptions!$B$24,0))*(1+Assumptions!$B$29) -> 2046 | AF8: =(L8)*AE8-(((D8)+(L8)*Assumptions!$B$4+IF(H8="Yes",Assumptions!$B$6*(D8),(L8)*Assumptions!$B$5))*(1+Assumptions!$B$7*(Assumptions!$B$8*(N8)*Assumptions!$B$9+Assumptions!$B$10))+(D8)*Assumptions!$B$11*(N8)+(L8)*AE8*(Assumptions!$B$12+Assumptions!$B$13+IF((L8)*AE8>=Assumptions!$B$16,Assumptions!$B$17,IF((L8)*AE8>=Assumptions!$B$14,Assumptions!$B$15,0)))) -> 2810169.4 | AG8: =(INDEX(Assumptions!$B$36:$B$48,MATCH(AK8,Assumptions!$A$36:$A$48,0))+IF(I8="Yes",Assumptions!$B$23,0)+IF(J8="Yes",Assumptions!$B$24,0))*(1+Assumptions!$B$30) -> 2232 | AH8: =(L8)*AG8-(((D8)+(L8)*Assumptions!$B$4+IF(H8="Yes",Assumptions!$B$6*(D8),(L8)*Assumptions!$B$5))*(1+Assumptions!$B$7*(Assumptions!$B$8*(N8)*Assumptions!$B$9+Assumptions!$B$10))+(D8)*Assumptions!$B$11*(N8)+(L8)*AG8*(Assumptions!$B$12+Assumptions!$B$13+IF((L8)*AG8>=Assumptions!$B$16,Assumptions!$B$17,IF((L8)*AG8>=Assumptions!$B$14,Assumptions!$B$15,0)))) -> 4044556 | AI8: =(L8)*AE8-(((D8)+(L8)*Assumptions!$B$25+IF(H8="Yes",Assumptions!$B$6*(D8),(L8)*Assumptions!$B$5))*(1+Assumptions!$B$7*(Assumptions!$B$8*(N8)*Assumptions!$B$9+Assumptions!$B$10))+(D8)*Assumptions!$B$11*(N8)+(L8)*AE8*(Assumptions!$B$12+Assumptions!$B$13+IF((L8)*AE8>=Assumptions!$B$16,Assumptions!$B$17,IF((L8)*AE8>=Assumptions!$B$14,Assumptions!$B$15,0)))) -> 3223574 | AJ8: =(L8)*AE8-(((D8)+(L8)*Assumptions!$B$26+IF(H8="Yes",Assumptions!$B$6*(D8),(L8)*Assumptions!$B$5))*(1+Assumptions!$B$7*(Assumptions!$B$8*(N8)*Assumptions!$B$9+Assumptions!$B$10))+(D8)*Assumptions!$B$11*(N8)+(L8)*AE8*(Assumptions!$B$12+Assumptions!$B$13+IF((L8)*AE8>=Assumptions!$B$16,Assumptions!$B$17,IF((L8)*AE8>=Assumptions!$B$14,Assumptions!$B$15,0)))) -> 3636978.5 | AK8: RIV | AL8: =IF(G8>0,G8,ROUND(F8*Assumptions!$B$18,0)) -> 3579 | AM8: =IF(H8="Yes",AL8,MAX(AL8,MIN(Assumptions!$B$20,ROUND(E8*Assumptions!$B$19,0)))) -> 7338 | AN8: =(AL8)*AE8-(((D8)+(AL8)*Assumptions!$B$4+IF(H8="Yes",Assumptions!$B$6*(D8),(AL8)*Assumptions!$B$5))*(1+Assumptions!$B$7*(Assumptions!$B$8*(Assumptions!$B$21)*Assumptions!$B$9+Assumptions!$B$10))+(D8)*Assumptions!$B$11*(Assumptions!$B$21)+(AL8)*AE8*(Assumptions!$B$12+Assumptions!$B$13+IF((AL8)*AE8>=Assumptions!$B$16,Assumptions!$B$17,IF((AL8)*AE8>=Assumptions!$B$14,Assumptions!$B$15,0)))) -> -453752.17 | AO8: =(AM8)*AE8-(((D8)+(AM8)*Assumptions!$B$4+IF(H8="Yes",Assumptions!$B$6*(D8),(AM8)*Assumptions!$B$5))*(1+Assumptions!$B$7*(Assumptions!$B$8*(IF(AM8>AL8,Assumptions!$B$22,Assumptions!$B$21))*Assumptions!$B$9+Assumptions!$B$10))+(D8)*Assumptions!$B$11*(IF(AM8>AL8,Assumptions!$B$22,Assumptions!$B$21))+(AM8)*AE8*(Assumptions!$B$12+Assumptions!$B$13+IF((AM8)*AE8>=Assumptions!$B$16,Assumptions!$B$17,IF((AM8)*AE8>=Assumptions!$B$14,Assumptions!$B$15,0)))) -> 2810169.4 | AP8: =Assumptions!$B$7*(Q8+R8+S8) -> 6134017.5
A9: 7 | B9: 611 Ocampo Dr | C9: Huntington | D9: 4495000 | E9: 8205 | F9: 3513 | G9: 7154 | H9: Yes | I9: No | J9: No | K9: LADBS: plan check approved 7/31/26, 7,154 sf (listing 7,524); new pool permit issued | L9: =IF(AO9>AN9,AM9,AL9) -> 7154 | M9: =IF(AO9>AN9,"Zoning estimate",IF(H9="Yes","Approved plans",IF(G9>0,"Listing claim","110% old house"))) -> Approved plans | N9: =IF(AO9>AN9,IF(AM9>AL9,Assumptions!$B$22,Assumptions!$B$21),Assumptions!$B$21) -> 2 | O9: =(INDEX(Assumptions!$B$36:$B$48,MATCH(AK9,Assumptions!$A$36:$A$48,0))+IF(I9="Yes",Assumptions!$B$23,0)+IF(J9="Yes",Assumptions!$B$24,0))*(1+IF(UPPER(Assumptions!$B$31)="WORST",Assumptions!$B$28,IF(UPPER(Assumptions!$B$31)="BEST",Assumptions!$B$30,Assumptions!$B$29))) -> 2035 | P9: =L9*O9 -> 14558390 | Q9: =D9 -> 4495000 | R9: =L9*Assumptions!$B$4 -> 5007800 | S9: =IF(H9="Yes",Assumptions!$B$6*(D9),(L9)*Assumptions!$B$5) -> 224750 | T9: =AP9*(Assumptions!$B$8*N9*Assumptions!$B$9+Assumptions!$B$10) -> 853592.51 | U9: =Q9*Assumptions!$B$11*N9 -> 107880 | V9: =P9*(Assumptions!$B$12+Assumptions!$B$13) -> 591070.63 | W9: =P9*IF(P9>=Assumptions!$B$16,Assumptions!$B$17,IF(P9>=Assumptions!$B$14,Assumptions!$B$15,0)) -> 800711.45 | X9: =SUM(Q9:W9) -> 12080805 | Y9: =P9-X9 -> 2477585.4 | Z9: =IF(X9=0,0,Y9/X9) -> 0.20508447 | AA9: =MAX(0,(P9/(1+Assumptions!$B$27)-(L9*(Assumptions!$B$4+IF(H9="Yes",0,Assumptions!$B$5)))*(1+(Assumptions!$B$7*(Assumptions!$B$8*N9*Assumptions!$B$9+Assumptions!$B$10)))-P9*(Assumptions!$B$12+Assumptions!$B$13+IF(P9>=Assumptions!$B$16,Assumptions!$B$17,IF(P9>=Assumptions!$B$14,Assumptions!$B$15,0))))/((1+IF(H9="Yes",Assumptions!$B$6,0))*(1+(Assumptions!$B$7*(Assumptions!$B$8*N9*Assumptions!$B$9+Assumptions!$B$10)))+Assumptions!$B$11*N9)) -> 4991223.6 | AB9: =IF(AA9<=0,"no price works",D9/AA9) -> 0.90058077 | AC9: =(INDEX(Assumptions!$B$36:$B$48,MATCH(AK9,Assumptions!$A$36:$A$48,0))+IF(I9="Yes",Assumptions!$B$23,0)+IF(J9="Yes",Assumptions!$B$24,0))*(1+Assumptions!$B$28) -> 1850 | AD9: =(L9)*AC9-(((D9)+(L9)*Assumptions!$B$4+IF(H9="Yes",Assumptions!$B$6*(D9),(L9)*Assumptions!$B$5))*(1+Assumptions!$B$7*(Assumptions!$B$8*(N9)*Assumptions!$B$9+Assumptions!$B$10))+(D9)*Assumptions!$B$11*(N9)+(L9)*AC9*(Assumptions!$B$12+Assumptions!$B$13+IF((L9)*AC9>=Assumptions!$B$16,Assumptions!$B$17,IF((L9)*AC9>=Assumptions!$B$14,Assumptions!$B$15,0)))) -> 1280621 | AE9: =(INDEX(Assumptions!$B$36:$B$48,MATCH(AK9,Assumptions!$A$36:$A$48,0))+IF(I9="Yes",Assumptions!$B$23,0)+IF(J9="Yes",Assumptions!$B$24,0))*(1+Assumptions!$B$29) -> 2035 | AF9: =(L9)*AE9-(((D9)+(L9)*Assumptions!$B$4+IF(H9="Yes",Assumptions!$B$6*(D9),(L9)*Assumptions!$B$5))*(1+Assumptions!$B$7*(Assumptions!$B$8*(N9)*Assumptions!$B$9+Assumptions!$B$10))+(D9)*Assumptions!$B$11*(N9)+(L9)*AE9*(Assumptions!$B$12+Assumptions!$B$13+IF((L9)*AE9>=Assumptions!$B$16,Assumptions!$B$17,IF((L9)*AE9>=Assumptions!$B$14,Assumptions!$B$15,0)))) -> 2477585.4 | AG9: =(INDEX(Assumptions!$B$36:$B$48,MATCH(AK9,Assumptions!$A$36:$A$48,0))+IF(I9="Yes",Assumptions!$B$23,0)+IF(J9="Yes",Assumptions!$B$24,0))*(1+Assumptions!$B$30) -> 2220 | AH9: =(L9)*AG9-(((D9)+(L9)*Assumptions!$B$4+IF(H9="Yes",Assumptions!$B$6*(D9),(L9)*Assumptions!$B$5))*(1+Assumptions!$B$7*(Assumptions!$B$8*(N9)*Assumptions!$B$9+Assumptions!$B$10))+(D9)*Assumptions!$B$11*(N9)+(L9)*AG9*(Assumptions!$B$12+Assumptions!$B$13+IF((L9)*AG9>=Assumptions!$B$16,Assumptions!$B$17,IF((L9)*AG9>=Assumptions!$B$14,Assumptions!$B$15,0)))) -> 3674549.8 | AI9: =(L9)*AE9-(((D9)+(L9)*Assumptions!$B$25+IF(H9="Yes",Assumptions!$B$6*(D9),(L9)*Assumptions!$B$5))*(1+Assumptions!$B$7*(Assumptions!$B$8*(N9)*Assumptions!$B$9+Assumptions!$B$10))+(D9)*Assumptions!$B$11*(N9)+(L9)*AE9*(Assumptions!$B$12+Assumptions!$B$13+IF((L9)*AE9>=Assumptions!$B$16,Assumptions!$B$17,IF((L9)*AE9>=Assumptions!$B$14,Assumptions!$B$15,0)))) -> 2866673.6 | AJ9: =(L9)*AE9-(((D9)+(L9)*Assumptions!$B$26+IF(H9="Yes",Assumptions!$B$6*(D9),(L9)*Assumptions!$B$5))*(1+Assumptions!$B$7*(Assumptions!$B$8*(N9)*Assumptions!$B$9+Assumptions!$B$10))+(D9)*Assumptions!$B$11*(N9)+(L9)*AE9*(Assumptions!$B$12+Assumptions!$B$13+IF((L9)*AE9>=Assumptions!$B$16,Assumptions!$B$17,IF((L9)*AE9>=Assumptions!$B$14,Assumptions!$B$15,0)))) -> 3255761.8 | AK9: HUNT | AL9: =IF(G9>0,G9,ROUND(F9*Assumptions!$B$18,0)) -> 7154 | AM9: =IF(H9="Yes",AL9,MAX(AL9,MIN(Assumptions!$B$20,ROUND(E9*Assumptions!$B$19,0)))) -> 7154 | AN9: =(AL9)*AE9-(((D9)+(AL9)*Assumptions!$B$4+IF(H9="Yes",Assumptions!$B$6*(D9),(AL9)*Assumptions!$B$5))*(1+Assumptions!$B$7*(Assumptions!$B$8*(Assumptions!$B$21)*Assumptions!$B$9+Assumptions!$B$10))+(D9)*Assumptions!$B$11*(Assumptions!$B$21)+(AL9)*AE9*(Assumptions!$B$12+Assumptions!$B$13+IF((AL9)*AE9>=Assumptions!$B$16,Assumptions!$B$17,IF((AL9)*AE9>=Assumptions!$B$14,Assumptions!$B$15,0)))) -> 2477585.4 | AO9: =(AM9)*AE9-(((D9)+(AM9)*Assumptions!$B$4+IF(H9="Yes",Assumptions!$B$6*(D9),(AM9)*Assumptions!$B$5))*(1+Assumptions!$B$7*(Assumptions!$B$8*(IF(AM9>AL9,Assumptions!$B$22,Assumptions!$B$21))*Assumptions!$B$9+Assumptions!$B$10))+(D9)*Assumptions!$B$11*(IF(AM9>AL9,Assumptions!$B$22,Assumptions!$B$21))+(AM9)*AE9*(Assumptions!$B$12+Assumptions!$B$13+IF((AM9)*AE9>=Assumptions!$B$16,Assumptions!$B$17,IF((AM9)*AE9>=Assumptions!$B$14,Assumptions!$B$15,0)))) -> 2477585.4 | AP9: =Assumptions!$B$7*(Q9+R9+S9) -> 6322907.5
